<?xml version="1.0" ?>
<!-- =================================================================================== -->
<!-- |    This document was autogenerated by xacro from ezgripper_single_standalone.urdf.xacro | -->
<!-- |    EDITING THIS FILE BY HAND IS NOT RECOMMENDED                                 | -->
<!-- =================================================================================== -->
<robot name="ezgripper_single_mount">
  <material name="black">
    <color rgba="0.0 0.0 0.0 1.0"/>
  </material>
  <material name="blue">
    <color rgba="0.0 0.0 0.8 1.0"/>
  </material>
  <material name="grey">
    <color rgba="0.5 0.5 0.5 1"/>
  </material>
  <!-- Joints -->
  <!-- links -->
  <link name="left_ezgripper_mount">
    <visual>
      <origin rpy="0 0 0" xyz="0.0 0.0 0.0"/>
      <geometry>
        <mesh filename="package://ezgripper_description/meshes/visual/SAKE_Single_Mount.stl"/>
      </geometry>
      <material name="blue"/>
    </visual>
    <collision>
      <origin rpy="0 0 0" xyz="0.0 0.0 0.0"/>
      <geometry>
        <mesh filename="package://ezgripper_description/meshes/collision/SAKE_Single_Mount.stl"/>
      </geometry>
    </collision>
    <inertial>
      <mass value=".3"/>
      <inertia ixx="0.01" ixy="0.0" ixz="0.0" iyy="0.01" iyz="0.0" izz="0.01"/>
    </inertial>
  </link>
  <joint name="left_ezgripper_mount2base" type="fixed">
    <origin rpy="0 0 0" xyz="0.0 0.0 0.0"/>
    <parent link="base_link"/>
    <child link="left_ezgripper_mount"/>
    <axis xyz="0 0 0"/>
    <limit effort="0" lower="-1.57075" upper="0.25" velocity="3.67"/>
  </joint>
  <link name="left_ezgripper_palm_link">
    <visual>
      <origin rpy="0 0 0" xyz="0.0 0 0"/>
      <geometry>
        <mesh filename="package://ezgripper_description/meshes/visual/SAKE_Palm_IM.stl"/>
      </geometry>
      <material name="blue"/>
    </visual>
    <collision>
      <origin rpy="0 0 0" xyz="0.0 0 0"/>
      <geometry>
        <mesh filename="package://ezgripper_description/meshes/collision/SAKE_Palm_IM.stl"/>
      </geometry>
    </collision>
    <inertial>
      <mass value=".3"/>
      <inertia ixx="0.01" ixy="0.0" ixz="0.0" iyy="0.01" iyz="0.0" izz="0.01"/>
    </inertial>
  </link>
  <joint name="left_ezgripper_mount2palm" type="fixed">
    <origin rpy="0 0 0" xyz="0.016 0.0 0.0"/>
    <parent link="left_ezgripper_mount"/>
    <child link="left_ezgripper_palm_link"/>
    <axis xyz="0 0 0"/>
    <limit effort="0" lower="-1.57075" upper="0.25" velocity="3.67"/>
  </joint>
  <link name="left_ezgripper_finger_L1_1">
    <visual>
      <origin rpy="0 0 0" xyz="0 0 0"/>
      <geometry>
        <mesh filename="package://ezgripper_description/meshes/visual/SAKE_Finger_L1_IM.stl"/>
      </geometry>
      <material name="grey"/>
    </visual>
    <collision>
      <origin rpy="0 0 0" xyz="0 0 0"/>
      <geometry>
        <mesh filename="package://ezgripper_description/meshes/collision/SAKE_Finger_L1_IM.stl"/>
      </geometry>
    </collision>
    <inertial>
      <mass value=".025"/>
      <inertia ixx="0.01" ixy="0.0" ixz="0.0" iyy="0.01" iyz="0.0" izz="0.01"/>
    </inertial>
  </link>
  <link name="left_ezgripper_finger_L1_2">
    <visual>
      <origin rpy="0 0 0" xyz="0 0 0"/>
      <geometry>
        <mesh filename="package://ezgripper_description/meshes/visual/SAKE_Finger_L1_IM.stl"/>
      </geometry>
      <material name="grey"/>
    </visual>
    <collision>
      <origin rpy="0 0 0" xyz="0 0 0"/>
      <geometry>
        <mesh filename="package://ezgripper_description/meshes/collision/SAKE_Finger_L1_IM.stl"/>
      </geometry>
    </collision>
    <inertial>
      <mass value=".025"/>
      <inertia ixx="0.01" ixy="0.0" ixz="0.0" iyy="0.01" iyz="0.0" izz="0.01"/>
    </inertial>
  </link>
  <link name="left_ezgripper_finger_L2_1">
    <visual>
      <origin rpy="0 0 0" xyz="0 0 0"/>
      <geometry>
        <mesh filename="package://ezgripper_description/meshes/visual/SAKE_Finger_L2_IM.stl"/>
      </geometry>
      <material name="grey"/>
    </visual>
    <collision>
      <origin rpy="0 0 0" xyz="0 0 0"/>
      <geometry>
        <mesh filename="package://ezgripper_description/meshes/collision/SAKE_Finger_L2_IM.stl"/>
      </geometry>
    </collision>
    <inertial>
      <mass value=".025"/>
      <inertia ixx="0.01" ixy="0.0" ixz="0.0" iyy="0.01" iyz="0.0" izz="0.01"/>
    </inertial>
  </link>
  <link name="left_ezgripper_finger_L2_2">
    <visual>
      <origin rpy="0 0 0" xyz="0 0 0"/>
      <geometry>
        <mesh filename="package://ezgripper_description/meshes/visual/SAKE_Finger_L2_IM.stl"/>
      </geometry>
      <material name="grey"/>
    </visual>
    <collision>
      <origin rpy="0 0 0" xyz="0 0 0"/>
      <geometry>
        <mesh filename="package://ezgripper_description/meshes/collision/SAKE_Finger_L2_IM.stl"/>
      </geometry>
    </collision>
    <inertial>
      <mass value=".025"/>
      <inertia ixx="0.01" ixy="0.0" ixz="0.0" iyy="0.01" iyz="0.0" izz="0.01"/>
    </inertial>
  </link>
  <link name="left_ezgripper_finger_pad_1">
    <visual>
      <origin rpy="0 0 0" xyz="0 0 0"/>
      <geometry>
        <mesh filename="package://ezgripper_description/meshes/visual/SAKE_Finger_Pad_IM.stl"/>
      </geometry>
      <material name="grey"/>
    </visual>
    <collision>
      <origin rpy="0 0 0" xyz="0 0 0"/>
      <geometry>
        <mesh filename="package://ezgripper_description/meshes/collision/SAKE_Finger_Pad_IM.stl"/>
      </geometry>
    </collision>
    <inertial>
      <mass value=".025"/>
      <inertia ixx="0.01" ixy="0.0" ixz="0.0" iyy="0.01" iyz="0.0" izz="0.01"/>
    </inertial>
  </link>
  <link name="left_ezgripper_finger_pad_2">
    <visual>
      <origin rpy="0 0 0" xyz="0 0 0"/>
      <geometry>
        <mesh filename="package://ezgripper_description/meshes/visual/SAKE_Finger_Pad_IM.stl"/>
      </geometry>
      <material name="grey"/>
    </visual>
    <collision>
      <origin rpy="0 0 0" xyz="0 0 0"/>
      <geometry>
        <mesh filename="package://ezgripper_description/meshes/collision/SAKE_Finger_Pad_IM.stl"/>
      </geometry>
    </collision>
    <inertial>
      <mass value=".025"/>
      <inertia ixx="0.01" ixy="0.0" ixz="0.0" iyy="0.01" iyz="0.0" izz="0.01"/>
    </inertial>
  </link>
  <joint name="left_ezgripper_knuckle_palm_L1_1" type="revolute">
    <parent link="left_ezgripper_palm_link"/>
    <child link="left_ezgripper_finger_L1_1"/>
    <origin rpy="-1.5708 0 0" xyz="0.0595 0.03 0"/>
    <axis xyz="0 1 0"/>
    <limit effort="1" lower="-1.57075" upper="0.27" velocity="3.67"/>
  </joint>
  <joint name="left_ezgripper_knuckle_palm_L1_2" type="revolute">
    <parent link="left_ezgripper_palm_link"/>
    <child link="left_ezgripper_finger_L1_2"/>
    <origin rpy="1.5708 0 0" xyz="0.0595 -0.03 0"/>
    <axis xyz="0 1 0"/>
    <limit effort="1" lower="-1.57075" upper="0.27" velocity="3.67"/>
    <mimic joint="left_ezgripper_knuckle_palm_L1_1"/>
  </joint>
  <joint name="left_ezgripper_knuckle_L1_L2_1" type="revolute">
    <parent link="left_ezgripper_finger_L1_1"/>
    <child link="left_ezgripper_finger_L2_1"/>
    <origin rpy="0 0 0" xyz="0.052 0 0"/>
    <axis xyz="0 1 0"/>
    <limit effort="1" lower="0" upper="1.57075" velocity="3.67"/>
  </joint>
  <joint name="left_ezgripper_knuckle_L1_L2_2" type="revolute">
    <parent link="left_ezgripper_finger_L1_2"/>
    <child link="left_ezgripper_finger_L2_2"/>
    <origin rpy="0 0 0" xyz="0.052 0 0"/>
    <axis xyz="0 1 0"/>
    <limit effort="1" lower="0" upper="1.57075" velocity="3.67"/>
  </joint>
  <joint name="left_ezgripper_joint_finger_pad1" type="fixed">
    <parent link="left_ezgripper_finger_L2_1"/>
    <child link="left_ezgripper_finger_pad_1"/>
    <origin rpy="0 -0.2318 0" xyz="0.01849 0 0"/>
    <axis xyz="0 1 0"/>
  </joint>
  <joint name="left_ezgripper_joint_finger_pad2" type="fixed">
    <parent link="left_ezgripper_finger_L2_2"/>
    <child link="left_ezgripper_finger_pad_2"/>
    <origin rpy="0 -0.2318 0" xyz="0.01849 0 0"/>
    <axis xyz="0 1 0"/>
  </joint>
  <link name="world"/>
  <joint name="fixed" type="fixed">
    <parent link="world"/>
    <child link="base_link"/>
  </joint>
  <link name="base_link"/>
</robot>

