<?xml version='1.0' encoding='utf8'?>
<robot name="summit_xl">
    
  
    
  <link name="rg2_base_link">
    <inertial>
      <origin rpy="0 0 0.006" xyz="-0.00033928396113482284 0.0001550803374992693 0.06397335096404132"/>
      <mass value="0.7151802197889529"/>
      <inertia ixx="0.001268" ixy="0.0" ixz="-1.2e-05" iyy="0.001154" iyz="3e-06" izz="0.000357"/>
    </inertial>
    <visual>
      <origin rpy="0 0 0.006" xyz="0 0 0"/>
      <geometry>
        <mesh filename="rg2_description/meshes/base_link.stl" scale="0.001 0.001 0.001"/>
      </geometry>
      <material name="LightGrey">
        <color rgba="0.7 0.7 0.7 1.0"/>
      </material>
    </visual>
    <collision>
      <origin rpy="0 0 0.006" xyz="0 0 0"/>
      <geometry>
        <mesh filename="rg2_description/meshes/base_link.stl" scale="0.001 0.001 0.001"/>
      </geometry>
    </collision>
  </link>
  <joint name="rg6_gripper_joint" type="fixed">
    <origin xyz="0 0 0.006" rpy="0 0 1.5708" />
    <parent link="ur5_tool0"/>
    <child link="rg2_base_link" />
  </joint>

  <link name="left_outer_link_1">
    <inertial>
      <origin rpy="0 0 0" xyz="0.009999996523330909 0.0017814726549052681 0.012228209292930586"/>
      <mass value="0.03836739327168093"/>
      <inertia ixx="1.4e-05" ixy="0.0" ixz="0.0" iyy="1.4e-05" iyz="-0.0" izz="3e-06"/>
    </inertial>
    <visual>
      <origin rpy="0 0 0" xyz="0.0103 -0.01705 -0.12275"/>
      <geometry>
        <mesh filename="rg2_description/meshes/left_outer_link_1.stl" scale="0.001 0.001 0.001"/>
      </geometry>
      <material name="LightGrey">
        <color rgba="0.7 0.7 0.7 1.0"/>
      </material>
    </visual>
    <collision>
      <origin rpy="0 0 0" xyz="0.0103 -0.01705 -0.12275"/>
      <geometry>
        <mesh filename="rg2_description/meshes/left_outer_link_1.stl" scale="0.001 0.001 0.001"/>
      </geometry>
    </collision>
  </link>

  <link name="left_finger_link_1">
    <inertial>
      <origin rpy="0 0 0" xyz="0.010012780774690653 -0.010687647568749598 0.027402616106703998"/>
      <mass value="0.02483517715757534"/>
      <inertia ixx="7e-06" ixy="-0.0" ixz="0.0" iyy="6e-06" iyz="2e-06" izz="1e-06"/>
    </inertial>
    <visual>
      <origin rpy="0 0 0" xyz="0.0103 -0.01902 -0.177715"/>
      <geometry>
        <mesh filename="rg2_description/meshes/left_finger_link_1.stl" scale="0.001 0.001 0.001"/>
      </geometry>
      <material name="Black">
        <color rgba="0.0 0.0 0.0 1.0"/>
      </material>
    </visual>
    <collision>
      <origin rpy="0 0 0" xyz="0.0103 -0.01902 -0.177715"/>
      <geometry>
        <mesh filename="rg2_description/meshes/left_finger_link_1.stl" scale="0.001 0.001 0.001"/>
      </geometry>
    </collision>
  </link>

  <link name="left_inner_link_1">
    <inertial>
      <origin rpy="0 0 0" xyz="0.010005296596915006 -0.0016937268392717038 -0.03516232888579532"/>
      <mass value="0.012641568013611078"/>
      <inertia ixx="5e-06" ixy="0.0" ixz="-0.0" iyy="6e-06" iyz="-0.0" izz="1e-06"/>
    </inertial>
    <visual>
      <origin rpy="0 0 0" xyz="0.0103 -0.00952 -0.194215"/>
      <geometry>
        <mesh filename="rg2_description/meshes/left_inner_link_1.stl" scale="0.001 0.001 0.001"/>
      </geometry>
      <material name="Black">
        <color rgba="0.0 0.0 0.0 1.0"/>
      </material>
    </visual>
    <collision>
      <origin rpy="0 0 0" xyz="0.0103 -0.00952 -0.194215"/>
      <geometry>
        <mesh filename="rg2_description/meshes/left_inner_link_1.stl" scale="0.001 0.001 0.001"/>
      </geometry>
    </collision>
  </link>

  <link name="right_outer_link_1">
    <inertial>
      <origin rpy="0 0 0" xyz="0.010000003486636795 -0.0017814726548893677 0.012228209293019432"/>
      <mass value="0.03836739327185006"/>
      <inertia ixx="1.4e-05" ixy="0.0" ixz="-0.0" iyy="1.4e-05" iyz="0.0" izz="3e-06"/>
    </inertial>
    <visual>
      <origin rpy="0 0 0" xyz="0.0103 0.01695 -0.12275"/>
      <geometry>
        <mesh filename="rg2_description/meshes/right_outer_link_1.stl" scale="0.001 0.001 0.001"/>
      </geometry>
      <material name="LightGrey">
        <color rgba="0.7 0.7 0.7 1.0"/>
      </material>
    </visual>
    <collision>
      <origin rpy="0 0 0" xyz="0.0103 0.01695 -0.12275"/>
      <geometry>
        <mesh filename="rg2_description/meshes/right_outer_link_1.stl" scale="0.001 0.001 0.001"/>
      </geometry>
    </collision>
  </link>

  <link name="right_finger_link_1">
    <inertial>
      <origin rpy="0 0 0" xyz="0.009987219235276384 0.010687647568778226 0.02740261610670347"/>
      <mass value="0.02483517715757534"/>
      <inertia ixx="7e-06" ixy="-0.0" ixz="-0.0" iyy="6e-06" iyz="-2e-06" izz="1e-06"/>
    </inertial>
    <visual>
      <origin rpy="0 0 0" xyz="0.0103 0.01892 -0.177715"/>
      <geometry>
        <mesh filename="rg2_description/meshes/right_finger_link_1.stl" scale="0.001 0.001 0.001"/>
      </geometry>
      <material name="Black">
        <color rgba="0.0 0.0 0.0 1.0"/>
      </material>
    </visual>
    <collision>
      <origin rpy="0 0 0" xyz="0.0103 0.01892 -0.177715"/>
      <geometry>
        <mesh filename="rg2_description/meshes/right_finger_link_1.stl" scale="0.001 0.001 0.001"/>
      </geometry>
    </collision>
  </link>

  <link name="right_inner_link_1">
    <inertial>
      <origin rpy="0 0 0" xyz="0.00999470341305246 0.001693726839305438 -0.035162328885795485"/>
      <mass value="0.012641568013611078"/>
      <inertia ixx="5e-06" ixy="0.0" ixz="0.0" iyy="6e-06" iyz="0.0" izz="1e-06"/>
    </inertial>
    <visual>
      <origin rpy="0 0 0" xyz="0.0103 0.00942 -0.194215"/>
      <geometry>
        <mesh filename="rg2_description/meshes/right_inner_link_1.stl" scale="0.001 0.001 0.001"/>
      </geometry>
      <material name="Black">
        <color rgba="0.0 0.0 0.0 1.0"/>
      </material>
    </visual>
    <collision>
      <origin rpy="0 0 0" xyz="0.0103 0.00942 -0.194215"/>
      <geometry>
        <mesh filename="rg2_description/meshes/right_inner_link_1.stl" scale="0.001 0.001 0.001"/>
      </geometry>
    </collision>
  </link>


  <joint name="Rev33" type="continuous">
    <origin rpy="0 0 0" xyz="-0.0103 0.01705 0.12275"/>
    <parent link="rg2_base_link"/>
    <child link="left_outer_link_1"/>
    <axis xyz="1.0 0.0 0.0"/>
    <mimic joint="Rev28" multiplier="-1.0" offset="0"/>
  </joint>

  <joint name="Rev29" type="continuous">
    <origin rpy="0 0 0" xyz="0.0 0.00197 0.054965"/>
    <parent link="left_outer_link_1"/>
    <child link="left_finger_link_1"/>
    <axis xyz="-1.0 -0.0 -0.0"/>
    <mimic joint="Rev28" multiplier="-1.0" offset="0"/>
  </joint>

  <joint name="Rev30" type="continuous">
    <origin rpy="0 0 0" xyz="0.0 -0.0095 0.0165"/>
    <parent link="left_finger_link_1"/>
    <child link="left_inner_link_1"/>
    <axis xyz="-1.0 -0.0 -0.0"/>
    <mimic joint="Rev28" multiplier="1.0" offset="0"/>
  </joint>

  <joint name="Rev28" type="revolute">
    <origin rpy="0 0 0" xyz="-0.0103 -0.01695 0.12275"/>
    <parent link="rg2_base_link"/>
    <child link="right_outer_link_1"/>
    <axis xyz="1.0 0.0 0.0"/>
    <limit effort="100" lower="0.0" upper="1.343904" velocity="100"/>
  </joint>

  <joint name="Rev34" type="continuous">
    <origin rpy="0 0 0" xyz="0.0 -0.00197 0.054965"/>
    <parent link="right_outer_link_1"/>
    <child link="right_finger_link_1"/>
    <axis xyz="-1.0 -0.0 -0.0"/>
    <mimic joint="Rev28" multiplier="1.0" offset="0"/>
  </joint>

  <joint name="Rev35" type="continuous">
    <origin rpy="0 0 0" xyz="0.0 0.0095 0.0165"/>
    <parent link="right_finger_link_1"/>
    <child link="right_inner_link_1"/>
    <axis xyz="-1.0 0.0 -0.0"/>
    <mimic joint="Rev28" multiplier="-1.0" offset="0"/>
  </joint>


  <joint name="camera_joint" type="fixed">
    <origin rpy="1.5708 -1.5708 0" xyz="0 -0.102 0.014" />
    <parent link="camera_bracket" />
    <child link="camera_bottom_screw_frame" />
  </joint>
  <link name="camera_bottom_screw_frame" />
  <joint name="camera_link_joint" type="fixed">
    <origin rpy="0 0 0" xyz="0.0106 0.0175 0.0125" />
    <parent link="camera_bottom_screw_frame" />
    <child link="camera_link" />
  </joint>
  <link name="camera_link">
    <visual>
      <origin rpy="1.57079632679 0 1.57079632679" xyz="0.0043 -0.0175 0" />
      <geometry>
        <mesh filename="d435_description/d435.dae" />
      </geometry>
      <material name="LightGrey">
        <color rgba="0.7 0.7 0.7 1.0"/>
      </material>
    </visual>
    <collision>
      <origin rpy="1.57079632679 0 1.57079632679" xyz="0.0043 -0.0175 0" />
      <geometry>
        <mesh filename="d435_description/d435.dae" />
      </geometry>
    </collision>
    <inertial>
      <mass value="0.564" />
      <origin xyz="0 0 0" />
      <inertia ixx="0.003881243" ixy="0.0" ixz="0.0" iyy="0.000498940" iyz="0.0" izz="0.003879257" />
    </inertial>
  </link>
  
  
  
  <joint name="camera_depth_joint" type="fixed">
    <origin rpy="0 0 0" xyz="0 0 0" />
    <parent link="camera_link" />
    <child link="camera_depth_frame" />
  </joint>
  <link name="camera_depth_frame" />
  <joint name="camera_depth_optical_joint" type="fixed">
    <origin rpy="-1.57079632679 0 -1.57079632679" xyz="0 0 0" />
    <parent link="camera_depth_frame" />
    <child link="camera_depth_optical_frame" />
  </joint>
  <link name="camera_depth_optical_frame" />
  
  <joint name="camera_infra1_joint" type="fixed">
    <origin rpy="0 0 0" xyz="0 0.0 0" />
    <parent link="camera_link" />
    <child link="camera_infra1_frame" />
  </joint>
  <link name="camera_infra1_frame" />
  <joint name="camera_infra1_optical_joint" type="fixed">
    <origin rpy="-1.57079632679 0 -1.57079632679" xyz="0 0 0" />
    <parent link="camera_infra1_frame" />
    <child link="camera_infra1_optical_frame" />
  </joint>
  <link name="camera_infra1_optical_frame" />
  
  <joint name="camera_infra2_joint" type="fixed">
    <origin rpy="0 0 0" xyz="0 -0.05 0" />
    <parent link="camera_link" />
    <child link="camera_infra2_frame" />
  </joint>
  <link name="camera_infra2_frame" />
  <joint name="camera_infra2_optical_joint" type="fixed">
    <origin rpy="-1.57079632679 0 -1.57079632679" xyz="0 0 0" />
    <parent link="camera_infra2_frame" />
    <child link="camera_infra2_optical_frame" />
  </joint>
  <link name="camera_infra2_optical_frame" />
  
  <joint name="camera_color_joint" type="fixed">
    <origin rpy="0 0 0" xyz="0 0.015 0" />
    <parent link="camera_link" />
    <child link="camera_color_frame" />
  </joint>
  <link name="camera_color_frame" />
  <joint name="camera_color_optical_joint" type="fixed">
    <origin rpy="-1.57079632679 0 -1.57079632679" xyz="0 0 0" />
    <parent link="camera_color_frame" />
    <child link="camera_color_optical_frame" />
  </joint>
  <link name="camera_color_optical_frame" />
  
  
  
  
  <link name="ur5_base_link">
    <visual>
      <origin rpy="0 0 3.14159265359" xyz="0 0 0" />
      <geometry>
        <mesh filename="ur5_description/visual/base.dae" />
      </geometry>
      <material name="LightGrey">
        <color rgba="0.7 0.7 0.7 1.0" />
      </material>
    </visual>
    <collision>
      <origin rpy="0 0 3.14159265359" xyz="0 0 0" />
      <geometry>
        <mesh filename="ur5_description/collision/base.stl" />
      </geometry>
    </collision>
    <inertial>
      <mass value="4.0" />
      <origin rpy="0 0 0" xyz="0.0 0.0 0.0" />
      <inertia ixx="0.00443333156" ixy="0.0" ixz="0.0" iyy="0.00443333156" iyz="0.0" izz="0.0072" />
    </inertial>
  </link>
  <joint name="ur5_shoulder_pan_joint" type="revolute">
    <parent link="ur5_base_link" />
    <child link="ur5_shoulder_link" />
    <origin rpy="0 0 3.14161541291" xyz="0 0 0.0891466430647" />
    <axis xyz="0 0 1" />
    <limit effort="150.0" lower="-6.28318530718" upper="6.28318530718" velocity="3.15" />
    <dynamics damping="0.0" friction="0.0" />
  </joint>
  <link name="ur5_shoulder_link">
    <visual>
      <origin rpy="0 0 3.14159265359" xyz="0 0 0" />
      <geometry>
        <mesh filename="ur5_description/visual/shoulder.dae" />
      </geometry>
      <material name="UR-Blue">
        <color rgba="0.376 0.576 0.674 1.0"/>
      </material>
    </visual>
    <collision>
      <origin rpy="0 0 3.14159265359" xyz="0 0 0" />
      <geometry>
        <mesh filename="ur5_description/collision/shoulder.stl" />
      </geometry>
    </collision>
    <inertial>
      <mass value="3.7" />
      <origin rpy="0 0 0" xyz="0.0 0.0 0.0" />
      <inertia ixx="0.0149723523444" ixy="0.0" ixz="0.0" iyy="0.0149723523444" iyz="0.0" izz="0.01040625" />
    </inertial>
  </link>
  <joint name="ur5_shoulder_lift_joint" type="revolute">
    <parent link="ur5_shoulder_link" />
    <child link="ur5_upper_arm_link" />
    <origin rpy="1.57029006034 0 6.28004107998e-05" xyz="0.000146634111712 0 0" />
    <axis xyz="0 0 1" />
    <limit effort="150.0" lower="-6.28318530718" upper="6.28318530718" velocity="3.15" />
    <dynamics damping="0.0" friction="0.0" />
  </joint>
  <link name="ur5_upper_arm_link">
    <visual>
      <origin rpy="1.57079632679 0 -1.57079632679" xyz="0 0 0.136" />
      <geometry>
        <mesh filename="ur5_description/visual/upperarm.dae" />
      </geometry>
      <material name="LightGrey">
        <color rgba="0.7 0.7 0.7 1.0" />
      </material>
    </visual>
    <collision>
      <origin rpy="1.57079632679 0 -1.57079632679" xyz="0 0 0.136" />
      <geometry>
        <mesh filename="ur5_description/collision/upperarm.stl" />
      </geometry>
    </collision>
    <inertial>
      <mass value="8.393" />
      <origin rpy="0 1.57079632679 0" xyz="-0.212595837271 0.0 0.136" />
      <inertia ixx="0.133999758827" ixy="0.0" ixz="0.0" iyy="0.133999758827" iyz="0.0" izz="0.0151074" />
    </inertial>
  </link>
  <joint name="ur5_elbow_joint" type="revolute">
    <parent link="ur5_upper_arm_link" />
    <child link="ur5_forearm_link" />
    <origin rpy="0.000309149033959 0.00195055847639 4.0824780764e-06" xyz="-0.425191674542 0 0" />
    <axis xyz="0 0 1" />
    <limit effort="150.0" lower="-3.14159265359" upper="3.14159265359" velocity="3.15" />
    <dynamics damping="0.0" friction="0.0" />
  </joint>
  <link name="ur5_forearm_link">
    <visual>
      <origin rpy="1.57079632679 0 -1.57079632679" xyz="0 0 0.0165" />
      <geometry>
        <mesh filename="ur5_description/visual/forearm.dae" />
      </geometry>
      <material name="LightGrey">
        <color rgba="0.7 0.7 0.7 1.0" />
      </material>
    </visual>
    <collision>
      <origin rpy="1.57079632679 0 -1.57079632679" xyz="0 0 0.0165" />
      <geometry>
        <mesh filename="ur5_description/collision/forearm.stl" />
      </geometry>
    </collision>
    <inertial>
      <mass value="2.275" />
      <origin rpy="0 1.57079632679 0" xyz="-0.212595837271 0.0 0.0165" />
      <inertia ixx="0.031152672327" ixy="0.0" ixz="0.0" iyy="0.031152672327" iyz="0.0" izz="0.004095" />
    </inertial>
  </link>
  <joint name="ur5_wrist_1_joint" type="revolute">
    <parent link="ur5_forearm_link" />
    <child link="ur5_wrist_1_link" />
    <origin rpy="0.00946036710336 0.000178832082866 8.30825091703e-06" xyz="-0.391818649157 -0.00104589148922 0.110551765664" />
    <axis xyz="0 0 1" />
    <limit effort="28.0" lower="-6.28318530718" upper="6.28318530718" velocity="3.2" />
    <dynamics damping="0.0" friction="0.0" />
  </joint>
  <link name="ur5_wrist_1_link">
    <visual>
      <origin rpy="1.57079632679 0 0" xyz="0 0 -0.093" />
      <geometry>
        <mesh filename="ur5_description/visual/wrist1.dae" />
      </geometry>
      <material name="UR-Blue">
        <color rgba="0.376 0.576 0.674 1.0"/>
      </material>
    </visual>
    <collision>
      <origin rpy="1.57079632679 0 0" xyz="0 0 -0.093" />
      <geometry>
        <mesh filename="ur5_description/collision/wrist1.stl" />
      </geometry>
    </collision>
    <inertial>
      <mass value="1.219" />
      <origin rpy="0 0 0" xyz="0.0 0.0 0.0" />
      <inertia ixx="0.00262465340213" ixy="0.0" ixz="0.0" iyy="0.00262465340213" iyz="0.0" izz="0.0034284375" />
    </inertial>
  </link>
  <joint name="ur5_wrist_2_joint" type="revolute">
    <parent link="ur5_wrist_1_link" />
    <child link="ur5_wrist_2_link" />
    <origin rpy="1.56994050176 0 -5.70603441434e-05" xyz="-9.99516732222e-06 -0.0946702251887 8.10211688195e-05" />
    <axis xyz="0 0 1" />
    <limit effort="28.0" lower="-6.28318530718" upper="6.28318530718" velocity="3.2" />
    <dynamics damping="0.0" friction="0.0" />
  </joint>
  <link name="ur5_wrist_2_link">
    <visual>
      <origin rpy="0 0 0" xyz="0 0 -0.095" />
      <geometry>
        <mesh filename="ur5_description/visual/wrist2.dae" />
      </geometry>
      <material name="DarkGray">
        <color rgba="0.5 0.5 0.5 1.0"/>
      </material>
    </visual>
    <collision>
      <origin rpy="0 0 0" xyz="0 0 -0.095" />
      <geometry>
        <mesh filename="ur5_description/collision/wrist2.stl" />
      </geometry>
    </collision>
    <inertial>
      <mass value="1.219" />
      <origin rpy="0 0 0" xyz="0.0 0.0 0.0" />
      <inertia ixx="0.00178798457695" ixy="0.0" ixz="0.0" iyy="0.00178798457695" iyz="0.0" izz="0.0021942" />
    </inertial>
  </link>
  <joint name="ur5_wrist_3_joint" type="revolute">
    <parent link="ur5_wrist_2_link" />
    <child link="ur5_wrist_3_link" />
    <origin rpy="1.57124983379 3.14159265359 3.14154158585" xyz="6.79436941657e-05 0.0824691928246 3.74003585712e-05" />
    <axis xyz="0 0 1" />
    <limit effort="28.0" lower="-6.28318530718" upper="6.28318530718" velocity="3.2" />
    <dynamics damping="0.0" friction="0.0" />
  </joint>
  <link name="ur5_wrist_3_link">
    <visual>
      <origin rpy="1.57079632679 0 0" xyz="0 0 -0.0818" />
      <geometry>
        <mesh filename="ur5_description/visual/wrist3.dae" />
      </geometry>
      <material name="LightGrey">
        <color rgba="0.7 0.7 0.7 1.0" />
      </material>
    </visual>
    <collision>
      <origin rpy="1.57079632679 0 0" xyz="0 0 -0.0823" />
      <geometry>
        <mesh filename="ur5_description/collision/wrist3.stl" />
      </geometry>
    </collision>
    <inertial>
      <mass value="0.1879" />
      <origin rpy="0 0 0" xyz="0.0 0.0 -0.01525" />
      <inertia ixx="8.06247260834e-05" ixy="0.0" ixz="0.0" iyy="8.06247260834e-05" iyz="0.0" izz="0.0001321171875" />
    </inertial>
  </link>
  <joint name="ur5_ee_fixed_joint" type="fixed">
    <parent link="ur5_wrist_3_link" />
    <child link="ur5_ee_link" />
    <origin rpy="0.0 -1.57079632679 1.57079632679" xyz="0.0 0.0 0.0" />
  </joint>
  <link name="ur5_ee_link">
    <collision>
      <geometry>
        <box size="0.01 0.01 0.01" />
      </geometry>
      <origin rpy="0 0 0" xyz="-0.01 0 0" />
    </collision>
  </link>
  <joint name="ur5_wrist_3_passive_joint" type="fixed">
    <origin rpy="0 0 0" xyz="0 0 0" />
    <parent link="ur5_wrist_3_link" />
    <child link="ur5_tool0" />
  </joint>
  
  <link name="ur5_base" />
  <joint name="ur5_base_link-base_fixed_joint" type="fixed">
    
    <origin rpy="0 0 -3.14159265359" xyz="0 0 0" />
    <parent link="ur5_base_link" />
    <child link="ur5_base" />
  </joint>
  
  <link name="ur5_tool0" />
  <link name="camera_bracket">
    <visual>
      <origin rpy="1.5708 1.5708 0" xyz="0 0 0" />
      <geometry>
        <mesh filename="d435_description/camera_bracket.STL" />
      </geometry>
      <material name="LightGrey">
        <color rgba="0.7 0.7 0.7 1.0"/>
      </material>
    </visual>
    <collision>
      <origin rpy="1.5708 1.5708 0" xyz="0 0 0" />
      <geometry>
        <mesh filename="d435_description/camera_bracket.STL" />
      </geometry>
    </collision>
  </link>
  <joint name="camera_bracket_joint" type="fixed">
    <parent link="ur5_tool0" />
    <child link="camera_bracket" />
    <origin rpy="0 0 0" xyz="0 0 0.006" />
  </joint>
  
  <link name="graps_link" />
  <joint name="graps_link_joint" type="fixed">
    <parent link="ur5_tool0" />
    <child link="graps_link" />
    <origin rpy="0 0 0" xyz="0 0 0.25" />
  </joint>
  
<!--################################################
  ########          connect model                #####
  ####################################################-->

  <link name="world"/>
  <!-- connect gripper to arm -->

  <!-- connect arm to world -->
  <joint name="world_arm_joint" type="fixed">
    <parent link="world"/>
    <child link="ur5_base_link"/>
    <origin rpy="0.0 0.0 0" xyz="0 0 0"/>
  </joint>
  
  
  
  
</robot>
